ERROR | 2022-07-07 14:32:06,207 | main.py:41 | BOT WAS STARTED
NoneType: None
ERROR | 2022-07-07 14:40:21,076 | dispatcher.py:390 | Cause exception while getting updates.
Traceback (most recent call last):
  File "C:\Users\ww\PycharmProjects\autoshopDjimbo3.1\venv\lib\site-packages\aiogram\dispatcher\dispatcher.py", line 381, in start_polling
    updates = await self.bot.get_updates(
  File "C:\Users\ww\PycharmProjects\autoshopDjimbo3.1\venv\lib\site-packages\aiogram\bot\bot.py", line 110, in get_updates
    result = await self.request(api.Methods.GET_UPDATES, payload)
  File "C:\Users\ww\PycharmProjects\autoshopDjimbo3.1\venv\lib\site-packages\aiogram\bot\base.py", line 231, in request
    return await api.make_request(await self.get_session(), self.server, self.__token, method, data, files,
  File "C:\Users\ww\PycharmProjects\autoshopDjimbo3.1\venv\lib\site-packages\aiogram\bot\api.py", line 140, in make_request
    return check_result(method, response.content_type, response.status, await response.text())
  File "C:\Users\ww\PycharmProjects\autoshopDjimbo3.1\venv\lib\site-packages\aiogram\bot\api.py", line 119, in check_result
    exceptions.ConflictError.detect(description)
  File "C:\Users\ww\PycharmProjects\autoshopDjimbo3.1\venv\lib\site-packages\aiogram\utils\exceptions.py", line 140, in detect
    raise err(cls.text or description)
aiogram.utils.exceptions.TerminatedByOtherGetUpdates: Terminated by other getupdates request; make sure that only one bot instance is running
ERROR | 2022-07-07 14:40:31,311 | dispatcher.py:390 | Cause exception while getting updates.
Traceback (most recent call last):
  File "C:\Users\ww\PycharmProjects\autoshopDjimbo3.1\venv\lib\site-packages\aiogram\dispatcher\dispatcher.py", line 381, in start_polling
    updates = await self.bot.get_updates(
  File "C:\Users\ww\PycharmProjects\autoshopDjimbo3.1\venv\lib\site-packages\aiogram\bot\bot.py", line 110, in get_updates
    result = await self.request(api.Methods.GET_UPDATES, payload)
  File "C:\Users\ww\PycharmProjects\autoshopDjimbo3.1\venv\lib\site-packages\aiogram\bot\base.py", line 231, in request
    return await api.make_request(await self.get_session(), self.server, self.__token, method, data, files,
  File "C:\Users\ww\PycharmProjects\autoshopDjimbo3.1\venv\lib\site-packages\aiogram\bot\api.py", line 140, in make_request
    return check_result(method, response.content_type, response.status, await response.text())
  File "C:\Users\ww\PycharmProjects\autoshopDjimbo3.1\venv\lib\site-packages\aiogram\bot\api.py", line 119, in check_result
    exceptions.ConflictError.detect(description)
  File "C:\Users\ww\PycharmProjects\autoshopDjimbo3.1\venv\lib\site-packages\aiogram\utils\exceptions.py", line 140, in detect
    raise err(cls.text or description)
aiogram.utils.exceptions.TerminatedByOtherGetUpdates: Terminated by other getupdates request; make sure that only one bot instance is running
ERROR | 2022-07-07 14:40:41,521 | dispatcher.py:390 | Cause exception while getting updates.
Traceback (most recent call last):
  File "C:\Users\ww\PycharmProjects\autoshopDjimbo3.1\venv\lib\site-packages\aiogram\dispatcher\dispatcher.py", line 381, in start_polling
    updates = await self.bot.get_updates(
  File "C:\Users\ww\PycharmProjects\autoshopDjimbo3.1\venv\lib\site-packages\aiogram\bot\bot.py", line 110, in get_updates
    result = await self.request(api.Methods.GET_UPDATES, payload)
  File "C:\Users\ww\PycharmProjects\autoshopDjimbo3.1\venv\lib\site-packages\aiogram\bot\base.py", line 231, in request
    return await api.make_request(await self.get_session(), self.server, self.__token, method, data, files,
  File "C:\Users\ww\PycharmProjects\autoshopDjimbo3.1\venv\lib\site-packages\aiogram\bot\api.py", line 140, in make_request
    return check_result(method, response.content_type, response.status, await response.text())
  File "C:\Users\ww\PycharmProjects\autoshopDjimbo3.1\venv\lib\site-packages\aiogram\bot\api.py", line 119, in check_result
    exceptions.ConflictError.detect(description)
  File "C:\Users\ww\PycharmProjects\autoshopDjimbo3.1\venv\lib\site-packages\aiogram\utils\exceptions.py", line 140, in detect
    raise err(cls.text or description)
aiogram.utils.exceptions.TerminatedByOtherGetUpdates: Terminated by other getupdates request; make sure that only one bot instance is running
ERROR | 2022-07-07 14:40:51,731 | dispatcher.py:390 | Cause exception while getting updates.
Traceback (most recent call last):
  File "C:\Users\ww\PycharmProjects\autoshopDjimbo3.1\venv\lib\site-packages\aiogram\dispatcher\dispatcher.py", line 381, in start_polling
    updates = await self.bot.get_updates(
  File "C:\Users\ww\PycharmProjects\autoshopDjimbo3.1\venv\lib\site-packages\aiogram\bot\bot.py", line 110, in get_updates
    result = await self.request(api.Methods.GET_UPDATES, payload)
  File "C:\Users\ww\PycharmProjects\autoshopDjimbo3.1\venv\lib\site-packages\aiogram\bot\base.py", line 231, in request
    return await api.make_request(await self.get_session(), self.server, self.__token, method, data, files,
  File "C:\Users\ww\PycharmProjects\autoshopDjimbo3.1\venv\lib\site-packages\aiogram\bot\api.py", line 140, in make_request
    return check_result(method, response.content_type, response.status, await response.text())
  File "C:\Users\ww\PycharmProjects\autoshopDjimbo3.1\venv\lib\site-packages\aiogram\bot\api.py", line 119, in check_result
    exceptions.ConflictError.detect(description)
  File "C:\Users\ww\PycharmProjects\autoshopDjimbo3.1\venv\lib\site-packages\aiogram\utils\exceptions.py", line 140, in detect
    raise err(cls.text or description)
aiogram.utils.exceptions.TerminatedByOtherGetUpdates: Terminated by other getupdates request; make sure that only one bot instance is running
ERROR | 2022-07-07 14:41:01,935 | dispatcher.py:390 | Cause exception while getting updates.
Traceback (most recent call last):
  File "C:\Users\ww\PycharmProjects\autoshopDjimbo3.1\venv\lib\site-packages\aiogram\dispatcher\dispatcher.py", line 381, in start_polling
    updates = await self.bot.get_updates(
  File "C:\Users\ww\PycharmProjects\autoshopDjimbo3.1\venv\lib\site-packages\aiogram\bot\bot.py", line 110, in get_updates
    result = await self.request(api.Methods.GET_UPDATES, payload)
  File "C:\Users\ww\PycharmProjects\autoshopDjimbo3.1\venv\lib\site-packages\aiogram\bot\base.py", line 231, in request
    return await api.make_request(await self.get_session(), self.server, self.__token, method, data, files,
  File "C:\Users\ww\PycharmProjects\autoshopDjimbo3.1\venv\lib\site-packages\aiogram\bot\api.py", line 140, in make_request
    return check_result(method, response.content_type, response.status, await response.text())
  File "C:\Users\ww\PycharmProjects\autoshopDjimbo3.1\venv\lib\site-packages\aiogram\bot\api.py", line 119, in check_result
    exceptions.ConflictError.detect(description)
  File "C:\Users\ww\PycharmProjects\autoshopDjimbo3.1\venv\lib\site-packages\aiogram\utils\exceptions.py", line 140, in detect
    raise err(cls.text or description)
aiogram.utils.exceptions.TerminatedByOtherGetUpdates: Terminated by other getupdates request; make sure that only one bot instance is running
ERROR | 2022-07-07 14:41:12,153 | dispatcher.py:390 | Cause exception while getting updates.
Traceback (most recent call last):
  File "C:\Users\ww\PycharmProjects\autoshopDjimbo3.1\venv\lib\site-packages\aiogram\dispatcher\dispatcher.py", line 381, in start_polling
    updates = await self.bot.get_updates(
  File "C:\Users\ww\PycharmProjects\autoshopDjimbo3.1\venv\lib\site-packages\aiogram\bot\bot.py", line 110, in get_updates
    result = await self.request(api.Methods.GET_UPDATES, payload)
  File "C:\Users\ww\PycharmProjects\autoshopDjimbo3.1\venv\lib\site-packages\aiogram\bot\base.py", line 231, in request
    return await api.make_request(await self.get_session(), self.server, self.__token, method, data, files,
  File "C:\Users\ww\PycharmProjects\autoshopDjimbo3.1\venv\lib\site-packages\aiogram\bot\api.py", line 140, in make_request
    return check_result(method, response.content_type, response.status, await response.text())
  File "C:\Users\ww\PycharmProjects\autoshopDjimbo3.1\venv\lib\site-packages\aiogram\bot\api.py", line 119, in check_result
    exceptions.ConflictError.detect(description)
  File "C:\Users\ww\PycharmProjects\autoshopDjimbo3.1\venv\lib\site-packages\aiogram\utils\exceptions.py", line 140, in detect
    raise err(cls.text or description)
aiogram.utils.exceptions.TerminatedByOtherGetUpdates: Terminated by other getupdates request; make sure that only one bot instance is running
ERROR | 2022-07-07 14:41:22,366 | dispatcher.py:390 | Cause exception while getting updates.
Traceback (most recent call last):
  File "C:\Users\ww\PycharmProjects\autoshopDjimbo3.1\venv\lib\site-packages\aiogram\dispatcher\dispatcher.py", line 381, in start_polling
    updates = await self.bot.get_updates(
  File "C:\Users\ww\PycharmProjects\autoshopDjimbo3.1\venv\lib\site-packages\aiogram\bot\bot.py", line 110, in get_updates
    result = await self.request(api.Methods.GET_UPDATES, payload)
  File "C:\Users\ww\PycharmProjects\autoshopDjimbo3.1\venv\lib\site-packages\aiogram\bot\base.py", line 231, in request
    return await api.make_request(await self.get_session(), self.server, self.__token, method, data, files,
  File "C:\Users\ww\PycharmProjects\autoshopDjimbo3.1\venv\lib\site-packages\aiogram\bot\api.py", line 140, in make_request
    return check_result(method, response.content_type, response.status, await response.text())
  File "C:\Users\ww\PycharmProjects\autoshopDjimbo3.1\venv\lib\site-packages\aiogram\bot\api.py", line 119, in check_result
    exceptions.ConflictError.detect(description)
  File "C:\Users\ww\PycharmProjects\autoshopDjimbo3.1\venv\lib\site-packages\aiogram\utils\exceptions.py", line 140, in detect
    raise err(cls.text or description)
aiogram.utils.exceptions.TerminatedByOtherGetUpdates: Terminated by other getupdates request; make sure that only one bot instance is running
ERROR | 2022-07-07 14:41:32,562 | dispatcher.py:390 | Cause exception while getting updates.
Traceback (most recent call last):
  File "C:\Users\ww\PycharmProjects\autoshopDjimbo3.1\venv\lib\site-packages\aiogram\dispatcher\dispatcher.py", line 381, in start_polling
    updates = await self.bot.get_updates(
  File "C:\Users\ww\PycharmProjects\autoshopDjimbo3.1\venv\lib\site-packages\aiogram\bot\bot.py", line 110, in get_updates
    result = await self.request(api.Methods.GET_UPDATES, payload)
  File "C:\Users\ww\PycharmProjects\autoshopDjimbo3.1\venv\lib\site-packages\aiogram\bot\base.py", line 231, in request
    return await api.make_request(await self.get_session(), self.server, self.__token, method, data, files,
  File "C:\Users\ww\PycharmProjects\autoshopDjimbo3.1\venv\lib\site-packages\aiogram\bot\api.py", line 140, in make_request
    return check_result(method, response.content_type, response.status, await response.text())
  File "C:\Users\ww\PycharmProjects\autoshopDjimbo3.1\venv\lib\site-packages\aiogram\bot\api.py", line 119, in check_result
    exceptions.ConflictError.detect(description)
  File "C:\Users\ww\PycharmProjects\autoshopDjimbo3.1\venv\lib\site-packages\aiogram\utils\exceptions.py", line 140, in detect
    raise err(cls.text or description)
aiogram.utils.exceptions.TerminatedByOtherGetUpdates: Terminated by other getupdates request; make sure that only one bot instance is running
ERROR | 2022-07-07 14:41:42,782 | dispatcher.py:390 | Cause exception while getting updates.
Traceback (most recent call last):
  File "C:\Users\ww\PycharmProjects\autoshopDjimbo3.1\venv\lib\site-packages\aiogram\dispatcher\dispatcher.py", line 381, in start_polling
    updates = await self.bot.get_updates(
  File "C:\Users\ww\PycharmProjects\autoshopDjimbo3.1\venv\lib\site-packages\aiogram\bot\bot.py", line 110, in get_updates
    result = await self.request(api.Methods.GET_UPDATES, payload)
  File "C:\Users\ww\PycharmProjects\autoshopDjimbo3.1\venv\lib\site-packages\aiogram\bot\base.py", line 231, in request
    return await api.make_request(await self.get_session(), self.server, self.__token, method, data, files,
  File "C:\Users\ww\PycharmProjects\autoshopDjimbo3.1\venv\lib\site-packages\aiogram\bot\api.py", line 140, in make_request
    return check_result(method, response.content_type, response.status, await response.text())
  File "C:\Users\ww\PycharmProjects\autoshopDjimbo3.1\venv\lib\site-packages\aiogram\bot\api.py", line 119, in check_result
    exceptions.ConflictError.detect(description)
  File "C:\Users\ww\PycharmProjects\autoshopDjimbo3.1\venv\lib\site-packages\aiogram\utils\exceptions.py", line 140, in detect
    raise err(cls.text or description)
aiogram.utils.exceptions.TerminatedByOtherGetUpdates: Terminated by other getupdates request; make sure that only one bot instance is running
ERROR | 2022-07-07 14:41:53,004 | dispatcher.py:390 | Cause exception while getting updates.
Traceback (most recent call last):
  File "C:\Users\ww\PycharmProjects\autoshopDjimbo3.1\venv\lib\site-packages\aiogram\dispatcher\dispatcher.py", line 381, in start_polling
    updates = await self.bot.get_updates(
  File "C:\Users\ww\PycharmProjects\autoshopDjimbo3.1\venv\lib\site-packages\aiogram\bot\bot.py", line 110, in get_updates
    result = await self.request(api.Methods.GET_UPDATES, payload)
  File "C:\Users\ww\PycharmProjects\autoshopDjimbo3.1\venv\lib\site-packages\aiogram\bot\base.py", line 231, in request
    return await api.make_request(await self.get_session(), self.server, self.__token, method, data, files,
  File "C:\Users\ww\PycharmProjects\autoshopDjimbo3.1\venv\lib\site-packages\aiogram\bot\api.py", line 140, in make_request
    return check_result(method, response.content_type, response.status, await response.text())
  File "C:\Users\ww\PycharmProjects\autoshopDjimbo3.1\venv\lib\site-packages\aiogram\bot\api.py", line 119, in check_result
    exceptions.ConflictError.detect(description)
  File "C:\Users\ww\PycharmProjects\autoshopDjimbo3.1\venv\lib\site-packages\aiogram\utils\exceptions.py", line 140, in detect
    raise err(cls.text or description)
aiogram.utils.exceptions.TerminatedByOtherGetUpdates: Terminated by other getupdates request; make sure that only one bot instance is running
ERROR | 2022-07-07 14:42:03,220 | dispatcher.py:390 | Cause exception while getting updates.
Traceback (most recent call last):
  File "C:\Users\ww\PycharmProjects\autoshopDjimbo3.1\venv\lib\site-packages\aiogram\dispatcher\dispatcher.py", line 381, in start_polling
    updates = await self.bot.get_updates(
  File "C:\Users\ww\PycharmProjects\autoshopDjimbo3.1\venv\lib\site-packages\aiogram\bot\bot.py", line 110, in get_updates
    result = await self.request(api.Methods.GET_UPDATES, payload)
  File "C:\Users\ww\PycharmProjects\autoshopDjimbo3.1\venv\lib\site-packages\aiogram\bot\base.py", line 231, in request
    return await api.make_request(await self.get_session(), self.server, self.__token, method, data, files,
  File "C:\Users\ww\PycharmProjects\autoshopDjimbo3.1\venv\lib\site-packages\aiogram\bot\api.py", line 140, in make_request
    return check_result(method, response.content_type, response.status, await response.text())
  File "C:\Users\ww\PycharmProjects\autoshopDjimbo3.1\venv\lib\site-packages\aiogram\bot\api.py", line 119, in check_result
    exceptions.ConflictError.detect(description)
  File "C:\Users\ww\PycharmProjects\autoshopDjimbo3.1\venv\lib\site-packages\aiogram\utils\exceptions.py", line 140, in detect
    raise err(cls.text or description)
aiogram.utils.exceptions.TerminatedByOtherGetUpdates: Terminated by other getupdates request; make sure that only one bot instance is running
ERROR | 2022-07-07 14:42:13,474 | dispatcher.py:390 | Cause exception while getting updates.
Traceback (most recent call last):
  File "C:\Users\ww\PycharmProjects\autoshopDjimbo3.1\venv\lib\site-packages\aiogram\dispatcher\dispatcher.py", line 381, in start_polling
    updates = await self.bot.get_updates(
  File "C:\Users\ww\PycharmProjects\autoshopDjimbo3.1\venv\lib\site-packages\aiogram\bot\bot.py", line 110, in get_updates
    result = await self.request(api.Methods.GET_UPDATES, payload)
  File "C:\Users\ww\PycharmProjects\autoshopDjimbo3.1\venv\lib\site-packages\aiogram\bot\base.py", line 231, in request
    return await api.make_request(await self.get_session(), self.server, self.__token, method, data, files,
  File "C:\Users\ww\PycharmProjects\autoshopDjimbo3.1\venv\lib\site-packages\aiogram\bot\api.py", line 140, in make_request
    return check_result(method, response.content_type, response.status, await response.text())
  File "C:\Users\ww\PycharmProjects\autoshopDjimbo3.1\venv\lib\site-packages\aiogram\bot\api.py", line 119, in check_result
    exceptions.ConflictError.detect(description)
  File "C:\Users\ww\PycharmProjects\autoshopDjimbo3.1\venv\lib\site-packages\aiogram\utils\exceptions.py", line 140, in detect
    raise err(cls.text or description)
aiogram.utils.exceptions.TerminatedByOtherGetUpdates: Terminated by other getupdates request; make sure that only one bot instance is running
ERROR | 2022-07-07 14:42:23,680 | dispatcher.py:390 | Cause exception while getting updates.
Traceback (most recent call last):
  File "C:\Users\ww\PycharmProjects\autoshopDjimbo3.1\venv\lib\site-packages\aiogram\dispatcher\dispatcher.py", line 381, in start_polling
    updates = await self.bot.get_updates(
  File "C:\Users\ww\PycharmProjects\autoshopDjimbo3.1\venv\lib\site-packages\aiogram\bot\bot.py", line 110, in get_updates
    result = await self.request(api.Methods.GET_UPDATES, payload)
  File "C:\Users\ww\PycharmProjects\autoshopDjimbo3.1\venv\lib\site-packages\aiogram\bot\base.py", line 231, in request
    return await api.make_request(await self.get_session(), self.server, self.__token, method, data, files,
  File "C:\Users\ww\PycharmProjects\autoshopDjimbo3.1\venv\lib\site-packages\aiogram\bot\api.py", line 140, in make_request
    return check_result(method, response.content_type, response.status, await response.text())
  File "C:\Users\ww\PycharmProjects\autoshopDjimbo3.1\venv\lib\site-packages\aiogram\bot\api.py", line 119, in check_result
    exceptions.ConflictError.detect(description)
  File "C:\Users\ww\PycharmProjects\autoshopDjimbo3.1\venv\lib\site-packages\aiogram\utils\exceptions.py", line 140, in detect
    raise err(cls.text or description)
aiogram.utils.exceptions.TerminatedByOtherGetUpdates: Terminated by other getupdates request; make sure that only one bot instance is running
ERROR | 2022-07-07 14:42:33,915 | dispatcher.py:390 | Cause exception while getting updates.
Traceback (most recent call last):
  File "C:\Users\ww\PycharmProjects\autoshopDjimbo3.1\venv\lib\site-packages\aiogram\dispatcher\dispatcher.py", line 381, in start_polling
    updates = await self.bot.get_updates(
  File "C:\Users\ww\PycharmProjects\autoshopDjimbo3.1\venv\lib\site-packages\aiogram\bot\bot.py", line 110, in get_updates
    result = await self.request(api.Methods.GET_UPDATES, payload)
  File "C:\Users\ww\PycharmProjects\autoshopDjimbo3.1\venv\lib\site-packages\aiogram\bot\base.py", line 231, in request
    return await api.make_request(await self.get_session(), self.server, self.__token, method, data, files,
  File "C:\Users\ww\PycharmProjects\autoshopDjimbo3.1\venv\lib\site-packages\aiogram\bot\api.py", line 140, in make_request
    return check_result(method, response.content_type, response.status, await response.text())
  File "C:\Users\ww\PycharmProjects\autoshopDjimbo3.1\venv\lib\site-packages\aiogram\bot\api.py", line 119, in check_result
    exceptions.ConflictError.detect(description)
  File "C:\Users\ww\PycharmProjects\autoshopDjimbo3.1\venv\lib\site-packages\aiogram\utils\exceptions.py", line 140, in detect
    raise err(cls.text or description)
aiogram.utils.exceptions.TerminatedByOtherGetUpdates: Terminated by other getupdates request; make sure that only one bot instance is running
ERROR | 2022-07-07 14:42:44,116 | dispatcher.py:390 | Cause exception while getting updates.
Traceback (most recent call last):
  File "C:\Users\ww\PycharmProjects\autoshopDjimbo3.1\venv\lib\site-packages\aiogram\dispatcher\dispatcher.py", line 381, in start_polling
    updates = await self.bot.get_updates(
  File "C:\Users\ww\PycharmProjects\autoshopDjimbo3.1\venv\lib\site-packages\aiogram\bot\bot.py", line 110, in get_updates
    result = await self.request(api.Methods.GET_UPDATES, payload)
  File "C:\Users\ww\PycharmProjects\autoshopDjimbo3.1\venv\lib\site-packages\aiogram\bot\base.py", line 231, in request
    return await api.make_request(await self.get_session(), self.server, self.__token, method, data, files,
  File "C:\Users\ww\PycharmProjects\autoshopDjimbo3.1\venv\lib\site-packages\aiogram\bot\api.py", line 140, in make_request
    return check_result(method, response.content_type, response.status, await response.text())
  File "C:\Users\ww\PycharmProjects\autoshopDjimbo3.1\venv\lib\site-packages\aiogram\bot\api.py", line 119, in check_result
    exceptions.ConflictError.detect(description)
  File "C:\Users\ww\PycharmProjects\autoshopDjimbo3.1\venv\lib\site-packages\aiogram\utils\exceptions.py", line 140, in detect
    raise err(cls.text or description)
aiogram.utils.exceptions.TerminatedByOtherGetUpdates: Terminated by other getupdates request; make sure that only one bot instance is running
ERROR | 2022-07-07 14:42:54,335 | dispatcher.py:390 | Cause exception while getting updates.
Traceback (most recent call last):
  File "C:\Users\ww\PycharmProjects\autoshopDjimbo3.1\venv\lib\site-packages\aiogram\dispatcher\dispatcher.py", line 381, in start_polling
    updates = await self.bot.get_updates(
  File "C:\Users\ww\PycharmProjects\autoshopDjimbo3.1\venv\lib\site-packages\aiogram\bot\bot.py", line 110, in get_updates
    result = await self.request(api.Methods.GET_UPDATES, payload)
  File "C:\Users\ww\PycharmProjects\autoshopDjimbo3.1\venv\lib\site-packages\aiogram\bot\base.py", line 231, in request
    return await api.make_request(await self.get_session(), self.server, self.__token, method, data, files,
  File "C:\Users\ww\PycharmProjects\autoshopDjimbo3.1\venv\lib\site-packages\aiogram\bot\api.py", line 140, in make_request
    return check_result(method, response.content_type, response.status, await response.text())
  File "C:\Users\ww\PycharmProjects\autoshopDjimbo3.1\venv\lib\site-packages\aiogram\bot\api.py", line 119, in check_result
    exceptions.ConflictError.detect(description)
  File "C:\Users\ww\PycharmProjects\autoshopDjimbo3.1\venv\lib\site-packages\aiogram\utils\exceptions.py", line 140, in detect
    raise err(cls.text or description)
aiogram.utils.exceptions.TerminatedByOtherGetUpdates: Terminated by other getupdates request; make sure that only one bot instance is running
ERROR | 2022-07-07 14:43:04,559 | dispatcher.py:390 | Cause exception while getting updates.
Traceback (most recent call last):
  File "C:\Users\ww\PycharmProjects\autoshopDjimbo3.1\venv\lib\site-packages\aiogram\dispatcher\dispatcher.py", line 381, in start_polling
    updates = await self.bot.get_updates(
  File "C:\Users\ww\PycharmProjects\autoshopDjimbo3.1\venv\lib\site-packages\aiogram\bot\bot.py", line 110, in get_updates
    result = await self.request(api.Methods.GET_UPDATES, payload)
  File "C:\Users\ww\PycharmProjects\autoshopDjimbo3.1\venv\lib\site-packages\aiogram\bot\base.py", line 231, in request
    return await api.make_request(await self.get_session(), self.server, self.__token, method, data, files,
  File "C:\Users\ww\PycharmProjects\autoshopDjimbo3.1\venv\lib\site-packages\aiogram\bot\api.py", line 140, in make_request
    return check_result(method, response.content_type, response.status, await response.text())
  File "C:\Users\ww\PycharmProjects\autoshopDjimbo3.1\venv\lib\site-packages\aiogram\bot\api.py", line 119, in check_result
    exceptions.ConflictError.detect(description)
  File "C:\Users\ww\PycharmProjects\autoshopDjimbo3.1\venv\lib\site-packages\aiogram\utils\exceptions.py", line 140, in detect
    raise err(cls.text or description)
aiogram.utils.exceptions.TerminatedByOtherGetUpdates: Terminated by other getupdates request; make sure that only one bot instance is running
ERROR | 2022-07-07 14:43:14,778 | dispatcher.py:390 | Cause exception while getting updates.
Traceback (most recent call last):
  File "C:\Users\ww\PycharmProjects\autoshopDjimbo3.1\venv\lib\site-packages\aiogram\dispatcher\dispatcher.py", line 381, in start_polling
    updates = await self.bot.get_updates(
  File "C:\Users\ww\PycharmProjects\autoshopDjimbo3.1\venv\lib\site-packages\aiogram\bot\bot.py", line 110, in get_updates
    result = await self.request(api.Methods.GET_UPDATES, payload)
  File "C:\Users\ww\PycharmProjects\autoshopDjimbo3.1\venv\lib\site-packages\aiogram\bot\base.py", line 231, in request
    return await api.make_request(await self.get_session(), self.server, self.__token, method, data, files,
  File "C:\Users\ww\PycharmProjects\autoshopDjimbo3.1\venv\lib\site-packages\aiogram\bot\api.py", line 140, in make_request
    return check_result(method, response.content_type, response.status, await response.text())
  File "C:\Users\ww\PycharmProjects\autoshopDjimbo3.1\venv\lib\site-packages\aiogram\bot\api.py", line 119, in check_result
    exceptions.ConflictError.detect(description)
  File "C:\Users\ww\PycharmProjects\autoshopDjimbo3.1\venv\lib\site-packages\aiogram\utils\exceptions.py", line 140, in detect
    raise err(cls.text or description)
aiogram.utils.exceptions.TerminatedByOtherGetUpdates: Terminated by other getupdates request; make sure that only one bot instance is running
ERROR | 2022-07-07 14:43:20,082 | z_all_errors.py:64 | Exception: Message is not modified: specified new message content and reply markup are exactly the same as a current content and reply markup of the message
Update: {"update_id": 674860867, "callback_query": {"id": "7857691771262626348", "from": {"id": 1829511432, "is_bot": false, "first_name": "Дархан", "username": "DarkhanMUR123", "language_code": "ru"}, "message": {"message_id": 4372, "from": {"id": 5436942647, "is_bot": true, "first_name": "my test bot", "username": "my_test_telegram_py_bot"}, "chat": {"id": 1829511432, "first_name": "Дархан", "username": "DarkhanMUR123", "type": "private"}, "date": 1657204836, "edit_date": 1657204867, "text": "💰 Выберите способ пополнения", "entities": [{"type": "bold", "offset": 0, "length": 29}], "reply_markup": {"inline_keyboard": [[{"text": "📋 QIWI форма", "callback_data": "refill_choice:Form"}], [{"text": "⬅ Вернуться ↩", "callback_data": "user_profile"}]]}}, "chat_instance": "-8506083230358799411", "data": "refill_choice:Form"}}
Traceback (most recent call last):
  File "C:\Users\ww\PycharmProjects\autoshopDjimbo3.1\venv\lib\site-packages\aiogram\dispatcher\dispatcher.py", line 283, in process_update
    return await self.callback_query_handlers.notify(update.callback_query)
  File "C:\Users\ww\PycharmProjects\autoshopDjimbo3.1\venv\lib\site-packages\aiogram\dispatcher\handler.py", line 116, in notify
    response = await handler_obj.handler(*args, **partial_data)
  File "C:\Users\ww\PycharmProjects\autoshopDjimbo3.1\tgbot\handlers\user_transactions.py", line 34, in refill_way_choice
    await call.message.edit_text("<b>💰 Введите сумму пополнения</b>")
  File "C:\Users\ww\PycharmProjects\autoshopDjimbo3.1\venv\lib\site-packages\aiogram\types\message.py", line 2838, in edit_text
    return await self.bot.edit_message_text(
  File "C:\Users\ww\PycharmProjects\autoshopDjimbo3.1\venv\lib\site-packages\aiogram\bot\bot.py", line 2740, in edit_message_text
    result = await self.request(api.Methods.EDIT_MESSAGE_TEXT, payload)
  File "C:\Users\ww\PycharmProjects\autoshopDjimbo3.1\venv\lib\site-packages\aiogram\bot\base.py", line 231, in request
    return await api.make_request(await self.get_session(), self.server, self.__token, method, data, files,
  File "C:\Users\ww\PycharmProjects\autoshopDjimbo3.1\venv\lib\site-packages\aiogram\bot\api.py", line 140, in make_request
    return check_result(method, response.content_type, response.status, await response.text())
  File "C:\Users\ww\PycharmProjects\autoshopDjimbo3.1\venv\lib\site-packages\aiogram\bot\api.py", line 115, in check_result
    exceptions.BadRequest.detect(description)
  File "C:\Users\ww\PycharmProjects\autoshopDjimbo3.1\venv\lib\site-packages\aiogram\utils\exceptions.py", line 140, in detect
    raise err(cls.text or description)
aiogram.utils.exceptions.MessageNotModified: Message is not modified: specified new message content and reply markup are exactly the same as a current content and reply markup of the message
ERROR | 2022-07-07 14:43:20,099 | base_events.py:1744 | Task exception was never retrieved
future: <Task finished name='Task-297' coro=<Dispatcher._process_polling_updates() done, defined at C:\Users\ww\PycharmProjects\autoshopDjimbo3.1\venv\lib\site-packages\aiogram\dispatcher\dispatcher.py:407> exception=MessageNotModified('Message is not modified: specified new message content and reply markup are exactly the same as a current content and reply markup of the message')>
Traceback (most recent call last):
  File "C:\Users\ww\PycharmProjects\autoshopDjimbo3.1\venv\lib\site-packages\aiogram\dispatcher\dispatcher.py", line 415, in _process_polling_updates
    for responses in itertools.chain.from_iterable(await self.process_updates(updates, fast)):
  File "C:\Users\ww\PycharmProjects\autoshopDjimbo3.1\venv\lib\site-packages\aiogram\dispatcher\dispatcher.py", line 235, in process_updates
    return await asyncio.gather(*tasks)
  File "C:\Users\ww\PycharmProjects\autoshopDjimbo3.1\venv\lib\site-packages\aiogram\dispatcher\handler.py", line 116, in notify
    response = await handler_obj.handler(*args, **partial_data)
  File "C:\Users\ww\PycharmProjects\autoshopDjimbo3.1\venv\lib\site-packages\aiogram\dispatcher\dispatcher.py", line 283, in process_update
    return await self.callback_query_handlers.notify(update.callback_query)
  File "C:\Users\ww\PycharmProjects\autoshopDjimbo3.1\venv\lib\site-packages\aiogram\dispatcher\handler.py", line 116, in notify
    response = await handler_obj.handler(*args, **partial_data)
  File "C:\Users\ww\PycharmProjects\autoshopDjimbo3.1\tgbot\handlers\user_transactions.py", line 34, in refill_way_choice
    await call.message.edit_text("<b>💰 Введите сумму пополнения</b>")
  File "C:\Users\ww\PycharmProjects\autoshopDjimbo3.1\venv\lib\site-packages\aiogram\types\message.py", line 2838, in edit_text
    return await self.bot.edit_message_text(
  File "C:\Users\ww\PycharmProjects\autoshopDjimbo3.1\venv\lib\site-packages\aiogram\bot\bot.py", line 2740, in edit_message_text
    result = await self.request(api.Methods.EDIT_MESSAGE_TEXT, payload)
  File "C:\Users\ww\PycharmProjects\autoshopDjimbo3.1\venv\lib\site-packages\aiogram\bot\base.py", line 231, in request
    return await api.make_request(await self.get_session(), self.server, self.__token, method, data, files,
  File "C:\Users\ww\PycharmProjects\autoshopDjimbo3.1\venv\lib\site-packages\aiogram\bot\api.py", line 140, in make_request
    return check_result(method, response.content_type, response.status, await response.text())
  File "C:\Users\ww\PycharmProjects\autoshopDjimbo3.1\venv\lib\site-packages\aiogram\bot\api.py", line 115, in check_result
    exceptions.BadRequest.detect(description)
  File "C:\Users\ww\PycharmProjects\autoshopDjimbo3.1\venv\lib\site-packages\aiogram\utils\exceptions.py", line 140, in detect
    raise err(cls.text or description)
aiogram.utils.exceptions.MessageNotModified: Message is not modified: specified new message content and reply markup are exactly the same as a current content and reply markup of the message
ERROR | 2022-07-07 14:43:25,416 | dispatcher.py:390 | Cause exception while getting updates.
Traceback (most recent call last):
  File "C:\Users\ww\PycharmProjects\autoshopDjimbo3.1\venv\lib\site-packages\aiogram\dispatcher\dispatcher.py", line 381, in start_polling
    updates = await self.bot.get_updates(
  File "C:\Users\ww\PycharmProjects\autoshopDjimbo3.1\venv\lib\site-packages\aiogram\bot\bot.py", line 110, in get_updates
    result = await self.request(api.Methods.GET_UPDATES, payload)
  File "C:\Users\ww\PycharmProjects\autoshopDjimbo3.1\venv\lib\site-packages\aiogram\bot\base.py", line 231, in request
    return await api.make_request(await self.get_session(), self.server, self.__token, method, data, files,
  File "C:\Users\ww\PycharmProjects\autoshopDjimbo3.1\venv\lib\site-packages\aiogram\bot\api.py", line 140, in make_request
    return check_result(method, response.content_type, response.status, await response.text())
  File "C:\Users\ww\PycharmProjects\autoshopDjimbo3.1\venv\lib\site-packages\aiogram\bot\api.py", line 119, in check_result
    exceptions.ConflictError.detect(description)
  File "C:\Users\ww\PycharmProjects\autoshopDjimbo3.1\venv\lib\site-packages\aiogram\utils\exceptions.py", line 140, in detect
    raise err(cls.text or description)
aiogram.utils.exceptions.TerminatedByOtherGetUpdates: Terminated by other getupdates request; make sure that only one bot instance is running
ERROR | 2022-07-07 14:43:35,616 | dispatcher.py:390 | Cause exception while getting updates.
Traceback (most recent call last):
  File "C:\Users\ww\PycharmProjects\autoshopDjimbo3.1\venv\lib\site-packages\aiogram\dispatcher\dispatcher.py", line 381, in start_polling
    updates = await self.bot.get_updates(
  File "C:\Users\ww\PycharmProjects\autoshopDjimbo3.1\venv\lib\site-packages\aiogram\bot\bot.py", line 110, in get_updates
    result = await self.request(api.Methods.GET_UPDATES, payload)
  File "C:\Users\ww\PycharmProjects\autoshopDjimbo3.1\venv\lib\site-packages\aiogram\bot\base.py", line 231, in request
    return await api.make_request(await self.get_session(), self.server, self.__token, method, data, files,
  File "C:\Users\ww\PycharmProjects\autoshopDjimbo3.1\venv\lib\site-packages\aiogram\bot\api.py", line 140, in make_request
    return check_result(method, response.content_type, response.status, await response.text())
  File "C:\Users\ww\PycharmProjects\autoshopDjimbo3.1\venv\lib\site-packages\aiogram\bot\api.py", line 119, in check_result
    exceptions.ConflictError.detect(description)
  File "C:\Users\ww\PycharmProjects\autoshopDjimbo3.1\venv\lib\site-packages\aiogram\utils\exceptions.py", line 140, in detect
    raise err(cls.text or description)
aiogram.utils.exceptions.TerminatedByOtherGetUpdates: Terminated by other getupdates request; make sure that only one bot instance is running
ERROR | 2022-07-07 14:43:45,809 | dispatcher.py:390 | Cause exception while getting updates.
Traceback (most recent call last):
  File "C:\Users\ww\PycharmProjects\autoshopDjimbo3.1\venv\lib\site-packages\aiogram\dispatcher\dispatcher.py", line 381, in start_polling
    updates = await self.bot.get_updates(
  File "C:\Users\ww\PycharmProjects\autoshopDjimbo3.1\venv\lib\site-packages\aiogram\bot\bot.py", line 110, in get_updates
    result = await self.request(api.Methods.GET_UPDATES, payload)
  File "C:\Users\ww\PycharmProjects\autoshopDjimbo3.1\venv\lib\site-packages\aiogram\bot\base.py", line 231, in request
    return await api.make_request(await self.get_session(), self.server, self.__token, method, data, files,
  File "C:\Users\ww\PycharmProjects\autoshopDjimbo3.1\venv\lib\site-packages\aiogram\bot\api.py", line 140, in make_request
    return check_result(method, response.content_type, response.status, await response.text())
  File "C:\Users\ww\PycharmProjects\autoshopDjimbo3.1\venv\lib\site-packages\aiogram\bot\api.py", line 119, in check_result
    exceptions.ConflictError.detect(description)
  File "C:\Users\ww\PycharmProjects\autoshopDjimbo3.1\venv\lib\site-packages\aiogram\utils\exceptions.py", line 140, in detect
    raise err(cls.text or description)
aiogram.utils.exceptions.TerminatedByOtherGetUpdates: Terminated by other getupdates request; make sure that only one bot instance is running
ERROR | 2022-07-07 14:43:56,026 | dispatcher.py:390 | Cause exception while getting updates.
Traceback (most recent call last):
  File "C:\Users\ww\PycharmProjects\autoshopDjimbo3.1\venv\lib\site-packages\aiogram\dispatcher\dispatcher.py", line 381, in start_polling
    updates = await self.bot.get_updates(
  File "C:\Users\ww\PycharmProjects\autoshopDjimbo3.1\venv\lib\site-packages\aiogram\bot\bot.py", line 110, in get_updates
    result = await self.request(api.Methods.GET_UPDATES, payload)
  File "C:\Users\ww\PycharmProjects\autoshopDjimbo3.1\venv\lib\site-packages\aiogram\bot\base.py", line 231, in request
    return await api.make_request(await self.get_session(), self.server, self.__token, method, data, files,
  File "C:\Users\ww\PycharmProjects\autoshopDjimbo3.1\venv\lib\site-packages\aiogram\bot\api.py", line 140, in make_request
    return check_result(method, response.content_type, response.status, await response.text())
  File "C:\Users\ww\PycharmProjects\autoshopDjimbo3.1\venv\lib\site-packages\aiogram\bot\api.py", line 119, in check_result
    exceptions.ConflictError.detect(description)
  File "C:\Users\ww\PycharmProjects\autoshopDjimbo3.1\venv\lib\site-packages\aiogram\utils\exceptions.py", line 140, in detect
    raise err(cls.text or description)
aiogram.utils.exceptions.TerminatedByOtherGetUpdates: Terminated by other getupdates request; make sure that only one bot instance is running
ERROR | 2022-07-07 14:44:06,241 | dispatcher.py:390 | Cause exception while getting updates.
Traceback (most recent call last):
  File "C:\Users\ww\PycharmProjects\autoshopDjimbo3.1\venv\lib\site-packages\aiogram\dispatcher\dispatcher.py", line 381, in start_polling
    updates = await self.bot.get_updates(
  File "C:\Users\ww\PycharmProjects\autoshopDjimbo3.1\venv\lib\site-packages\aiogram\bot\bot.py", line 110, in get_updates
    result = await self.request(api.Methods.GET_UPDATES, payload)
  File "C:\Users\ww\PycharmProjects\autoshopDjimbo3.1\venv\lib\site-packages\aiogram\bot\base.py", line 231, in request
    return await api.make_request(await self.get_session(), self.server, self.__token, method, data, files,
  File "C:\Users\ww\PycharmProjects\autoshopDjimbo3.1\venv\lib\site-packages\aiogram\bot\api.py", line 140, in make_request
    return check_result(method, response.content_type, response.status, await response.text())
  File "C:\Users\ww\PycharmProjects\autoshopDjimbo3.1\venv\lib\site-packages\aiogram\bot\api.py", line 119, in check_result
    exceptions.ConflictError.detect(description)
  File "C:\Users\ww\PycharmProjects\autoshopDjimbo3.1\venv\lib\site-packages\aiogram\utils\exceptions.py", line 140, in detect
    raise err(cls.text or description)
aiogram.utils.exceptions.TerminatedByOtherGetUpdates: Terminated by other getupdates request; make sure that only one bot instance is running
ERROR | 2022-07-07 14:44:16,471 | dispatcher.py:390 | Cause exception while getting updates.
Traceback (most recent call last):
  File "C:\Users\ww\PycharmProjects\autoshopDjimbo3.1\venv\lib\site-packages\aiogram\dispatcher\dispatcher.py", line 381, in start_polling
    updates = await self.bot.get_updates(
  File "C:\Users\ww\PycharmProjects\autoshopDjimbo3.1\venv\lib\site-packages\aiogram\bot\bot.py", line 110, in get_updates
    result = await self.request(api.Methods.GET_UPDATES, payload)
  File "C:\Users\ww\PycharmProjects\autoshopDjimbo3.1\venv\lib\site-packages\aiogram\bot\base.py", line 231, in request
    return await api.make_request(await self.get_session(), self.server, self.__token, method, data, files,
  File "C:\Users\ww\PycharmProjects\autoshopDjimbo3.1\venv\lib\site-packages\aiogram\bot\api.py", line 140, in make_request
    return check_result(method, response.content_type, response.status, await response.text())
  File "C:\Users\ww\PycharmProjects\autoshopDjimbo3.1\venv\lib\site-packages\aiogram\bot\api.py", line 119, in check_result
    exceptions.ConflictError.detect(description)
  File "C:\Users\ww\PycharmProjects\autoshopDjimbo3.1\venv\lib\site-packages\aiogram\utils\exceptions.py", line 140, in detect
    raise err(cls.text or description)
aiogram.utils.exceptions.TerminatedByOtherGetUpdates: Terminated by other getupdates request; make sure that only one bot instance is running
ERROR | 2022-07-07 14:44:26,732 | dispatcher.py:390 | Cause exception while getting updates.
Traceback (most recent call last):
  File "C:\Users\ww\PycharmProjects\autoshopDjimbo3.1\venv\lib\site-packages\aiogram\dispatcher\dispatcher.py", line 381, in start_polling
    updates = await self.bot.get_updates(
  File "C:\Users\ww\PycharmProjects\autoshopDjimbo3.1\venv\lib\site-packages\aiogram\bot\bot.py", line 110, in get_updates
    result = await self.request(api.Methods.GET_UPDATES, payload)
  File "C:\Users\ww\PycharmProjects\autoshopDjimbo3.1\venv\lib\site-packages\aiogram\bot\base.py", line 231, in request
    return await api.make_request(await self.get_session(), self.server, self.__token, method, data, files,
  File "C:\Users\ww\PycharmProjects\autoshopDjimbo3.1\venv\lib\site-packages\aiogram\bot\api.py", line 140, in make_request
    return check_result(method, response.content_type, response.status, await response.text())
  File "C:\Users\ww\PycharmProjects\autoshopDjimbo3.1\venv\lib\site-packages\aiogram\bot\api.py", line 119, in check_result
    exceptions.ConflictError.detect(description)
  File "C:\Users\ww\PycharmProjects\autoshopDjimbo3.1\venv\lib\site-packages\aiogram\utils\exceptions.py", line 140, in detect
    raise err(cls.text or description)
aiogram.utils.exceptions.TerminatedByOtherGetUpdates: Terminated by other getupdates request; make sure that only one bot instance is running
ERROR | 2022-07-07 14:44:36,944 | dispatcher.py:390 | Cause exception while getting updates.
Traceback (most recent call last):
  File "C:\Users\ww\PycharmProjects\autoshopDjimbo3.1\venv\lib\site-packages\aiogram\dispatcher\dispatcher.py", line 381, in start_polling
    updates = await self.bot.get_updates(
  File "C:\Users\ww\PycharmProjects\autoshopDjimbo3.1\venv\lib\site-packages\aiogram\bot\bot.py", line 110, in get_updates
    result = await self.request(api.Methods.GET_UPDATES, payload)
  File "C:\Users\ww\PycharmProjects\autoshopDjimbo3.1\venv\lib\site-packages\aiogram\bot\base.py", line 231, in request
    return await api.make_request(await self.get_session(), self.server, self.__token, method, data, files,
  File "C:\Users\ww\PycharmProjects\autoshopDjimbo3.1\venv\lib\site-packages\aiogram\bot\api.py", line 140, in make_request
    return check_result(method, response.content_type, response.status, await response.text())
  File "C:\Users\ww\PycharmProjects\autoshopDjimbo3.1\venv\lib\site-packages\aiogram\bot\api.py", line 119, in check_result
    exceptions.ConflictError.detect(description)
  File "C:\Users\ww\PycharmProjects\autoshopDjimbo3.1\venv\lib\site-packages\aiogram\utils\exceptions.py", line 140, in detect
    raise err(cls.text or description)
aiogram.utils.exceptions.TerminatedByOtherGetUpdates: Terminated by other getupdates request; make sure that only one bot instance is running
ERROR | 2022-07-07 14:44:47,149 | dispatcher.py:390 | Cause exception while getting updates.
Traceback (most recent call last):
  File "C:\Users\ww\PycharmProjects\autoshopDjimbo3.1\venv\lib\site-packages\aiogram\dispatcher\dispatcher.py", line 381, in start_polling
    updates = await self.bot.get_updates(
  File "C:\Users\ww\PycharmProjects\autoshopDjimbo3.1\venv\lib\site-packages\aiogram\bot\bot.py", line 110, in get_updates
    result = await self.request(api.Methods.GET_UPDATES, payload)
  File "C:\Users\ww\PycharmProjects\autoshopDjimbo3.1\venv\lib\site-packages\aiogram\bot\base.py", line 231, in request
    return await api.make_request(await self.get_session(), self.server, self.__token, method, data, files,
  File "C:\Users\ww\PycharmProjects\autoshopDjimbo3.1\venv\lib\site-packages\aiogram\bot\api.py", line 140, in make_request
    return check_result(method, response.content_type, response.status, await response.text())
  File "C:\Users\ww\PycharmProjects\autoshopDjimbo3.1\venv\lib\site-packages\aiogram\bot\api.py", line 119, in check_result
    exceptions.ConflictError.detect(description)
  File "C:\Users\ww\PycharmProjects\autoshopDjimbo3.1\venv\lib\site-packages\aiogram\utils\exceptions.py", line 140, in detect
    raise err(cls.text or description)
aiogram.utils.exceptions.TerminatedByOtherGetUpdates: Terminated by other getupdates request; make sure that only one bot instance is running
ERROR | 2022-07-07 14:44:57,356 | dispatcher.py:390 | Cause exception while getting updates.
Traceback (most recent call last):
  File "C:\Users\ww\PycharmProjects\autoshopDjimbo3.1\venv\lib\site-packages\aiogram\dispatcher\dispatcher.py", line 381, in start_polling
    updates = await self.bot.get_updates(
  File "C:\Users\ww\PycharmProjects\autoshopDjimbo3.1\venv\lib\site-packages\aiogram\bot\bot.py", line 110, in get_updates
    result = await self.request(api.Methods.GET_UPDATES, payload)
  File "C:\Users\ww\PycharmProjects\autoshopDjimbo3.1\venv\lib\site-packages\aiogram\bot\base.py", line 231, in request
    return await api.make_request(await self.get_session(), self.server, self.__token, method, data, files,
  File "C:\Users\ww\PycharmProjects\autoshopDjimbo3.1\venv\lib\site-packages\aiogram\bot\api.py", line 140, in make_request
    return check_result(method, response.content_type, response.status, await response.text())
  File "C:\Users\ww\PycharmProjects\autoshopDjimbo3.1\venv\lib\site-packages\aiogram\bot\api.py", line 119, in check_result
    exceptions.ConflictError.detect(description)
  File "C:\Users\ww\PycharmProjects\autoshopDjimbo3.1\venv\lib\site-packages\aiogram\utils\exceptions.py", line 140, in detect
    raise err(cls.text or description)
aiogram.utils.exceptions.TerminatedByOtherGetUpdates: Terminated by other getupdates request; make sure that only one bot instance is running
ERROR | 2022-07-07 14:45:07,560 | dispatcher.py:390 | Cause exception while getting updates.
Traceback (most recent call last):
  File "C:\Users\ww\PycharmProjects\autoshopDjimbo3.1\venv\lib\site-packages\aiogram\dispatcher\dispatcher.py", line 381, in start_polling
    updates = await self.bot.get_updates(
  File "C:\Users\ww\PycharmProjects\autoshopDjimbo3.1\venv\lib\site-packages\aiogram\bot\bot.py", line 110, in get_updates
    result = await self.request(api.Methods.GET_UPDATES, payload)
  File "C:\Users\ww\PycharmProjects\autoshopDjimbo3.1\venv\lib\site-packages\aiogram\bot\base.py", line 231, in request
    return await api.make_request(await self.get_session(), self.server, self.__token, method, data, files,
  File "C:\Users\ww\PycharmProjects\autoshopDjimbo3.1\venv\lib\site-packages\aiogram\bot\api.py", line 140, in make_request
    return check_result(method, response.content_type, response.status, await response.text())
  File "C:\Users\ww\PycharmProjects\autoshopDjimbo3.1\venv\lib\site-packages\aiogram\bot\api.py", line 119, in check_result
    exceptions.ConflictError.detect(description)
  File "C:\Users\ww\PycharmProjects\autoshopDjimbo3.1\venv\lib\site-packages\aiogram\utils\exceptions.py", line 140, in detect
    raise err(cls.text or description)
aiogram.utils.exceptions.TerminatedByOtherGetUpdates: Terminated by other getupdates request; make sure that only one bot instance is running
ERROR | 2022-07-07 14:45:17,784 | dispatcher.py:390 | Cause exception while getting updates.
Traceback (most recent call last):
  File "C:\Users\ww\PycharmProjects\autoshopDjimbo3.1\venv\lib\site-packages\aiogram\dispatcher\dispatcher.py", line 381, in start_polling
    updates = await self.bot.get_updates(
  File "C:\Users\ww\PycharmProjects\autoshopDjimbo3.1\venv\lib\site-packages\aiogram\bot\bot.py", line 110, in get_updates
    result = await self.request(api.Methods.GET_UPDATES, payload)
  File "C:\Users\ww\PycharmProjects\autoshopDjimbo3.1\venv\lib\site-packages\aiogram\bot\base.py", line 231, in request
    return await api.make_request(await self.get_session(), self.server, self.__token, method, data, files,
  File "C:\Users\ww\PycharmProjects\autoshopDjimbo3.1\venv\lib\site-packages\aiogram\bot\api.py", line 140, in make_request
    return check_result(method, response.content_type, response.status, await response.text())
  File "C:\Users\ww\PycharmProjects\autoshopDjimbo3.1\venv\lib\site-packages\aiogram\bot\api.py", line 119, in check_result
    exceptions.ConflictError.detect(description)
  File "C:\Users\ww\PycharmProjects\autoshopDjimbo3.1\venv\lib\site-packages\aiogram\utils\exceptions.py", line 140, in detect
    raise err(cls.text or description)
aiogram.utils.exceptions.TerminatedByOtherGetUpdates: Terminated by other getupdates request; make sure that only one bot instance is running
ERROR | 2022-07-07 14:45:27,996 | dispatcher.py:390 | Cause exception while getting updates.
Traceback (most recent call last):
  File "C:\Users\ww\PycharmProjects\autoshopDjimbo3.1\venv\lib\site-packages\aiogram\dispatcher\dispatcher.py", line 381, in start_polling
    updates = await self.bot.get_updates(
  File "C:\Users\ww\PycharmProjects\autoshopDjimbo3.1\venv\lib\site-packages\aiogram\bot\bot.py", line 110, in get_updates
    result = await self.request(api.Methods.GET_UPDATES, payload)
  File "C:\Users\ww\PycharmProjects\autoshopDjimbo3.1\venv\lib\site-packages\aiogram\bot\base.py", line 231, in request
    return await api.make_request(await self.get_session(), self.server, self.__token, method, data, files,
  File "C:\Users\ww\PycharmProjects\autoshopDjimbo3.1\venv\lib\site-packages\aiogram\bot\api.py", line 140, in make_request
    return check_result(method, response.content_type, response.status, await response.text())
  File "C:\Users\ww\PycharmProjects\autoshopDjimbo3.1\venv\lib\site-packages\aiogram\bot\api.py", line 119, in check_result
    exceptions.ConflictError.detect(description)
  File "C:\Users\ww\PycharmProjects\autoshopDjimbo3.1\venv\lib\site-packages\aiogram\utils\exceptions.py", line 140, in detect
    raise err(cls.text or description)
aiogram.utils.exceptions.TerminatedByOtherGetUpdates: Terminated by other getupdates request; make sure that only one bot instance is running
ERROR | 2022-07-07 14:45:38,204 | dispatcher.py:390 | Cause exception while getting updates.
Traceback (most recent call last):
  File "C:\Users\ww\PycharmProjects\autoshopDjimbo3.1\venv\lib\site-packages\aiogram\dispatcher\dispatcher.py", line 381, in start_polling
    updates = await self.bot.get_updates(
  File "C:\Users\ww\PycharmProjects\autoshopDjimbo3.1\venv\lib\site-packages\aiogram\bot\bot.py", line 110, in get_updates
    result = await self.request(api.Methods.GET_UPDATES, payload)
  File "C:\Users\ww\PycharmProjects\autoshopDjimbo3.1\venv\lib\site-packages\aiogram\bot\base.py", line 231, in request
    return await api.make_request(await self.get_session(), self.server, self.__token, method, data, files,
  File "C:\Users\ww\PycharmProjects\autoshopDjimbo3.1\venv\lib\site-packages\aiogram\bot\api.py", line 140, in make_request
    return check_result(method, response.content_type, response.status, await response.text())
  File "C:\Users\ww\PycharmProjects\autoshopDjimbo3.1\venv\lib\site-packages\aiogram\bot\api.py", line 119, in check_result
    exceptions.ConflictError.detect(description)
  File "C:\Users\ww\PycharmProjects\autoshopDjimbo3.1\venv\lib\site-packages\aiogram\utils\exceptions.py", line 140, in detect
    raise err(cls.text or description)
aiogram.utils.exceptions.TerminatedByOtherGetUpdates: Terminated by other getupdates request; make sure that only one bot instance is running
ERROR | 2022-07-07 14:45:48,416 | dispatcher.py:390 | Cause exception while getting updates.
Traceback (most recent call last):
  File "C:\Users\ww\PycharmProjects\autoshopDjimbo3.1\venv\lib\site-packages\aiogram\dispatcher\dispatcher.py", line 381, in start_polling
    updates = await self.bot.get_updates(
  File "C:\Users\ww\PycharmProjects\autoshopDjimbo3.1\venv\lib\site-packages\aiogram\bot\bot.py", line 110, in get_updates
    result = await self.request(api.Methods.GET_UPDATES, payload)
  File "C:\Users\ww\PycharmProjects\autoshopDjimbo3.1\venv\lib\site-packages\aiogram\bot\base.py", line 231, in request
    return await api.make_request(await self.get_session(), self.server, self.__token, method, data, files,
  File "C:\Users\ww\PycharmProjects\autoshopDjimbo3.1\venv\lib\site-packages\aiogram\bot\api.py", line 140, in make_request
    return check_result(method, response.content_type, response.status, await response.text())
  File "C:\Users\ww\PycharmProjects\autoshopDjimbo3.1\venv\lib\site-packages\aiogram\bot\api.py", line 119, in check_result
    exceptions.ConflictError.detect(description)
  File "C:\Users\ww\PycharmProjects\autoshopDjimbo3.1\venv\lib\site-packages\aiogram\utils\exceptions.py", line 140, in detect
    raise err(cls.text or description)
aiogram.utils.exceptions.TerminatedByOtherGetUpdates: Terminated by other getupdates request; make sure that only one bot instance is running
ERROR | 2022-07-07 14:45:58,615 | dispatcher.py:390 | Cause exception while getting updates.
Traceback (most recent call last):
  File "C:\Users\ww\PycharmProjects\autoshopDjimbo3.1\venv\lib\site-packages\aiogram\dispatcher\dispatcher.py", line 381, in start_polling
    updates = await self.bot.get_updates(
  File "C:\Users\ww\PycharmProjects\autoshopDjimbo3.1\venv\lib\site-packages\aiogram\bot\bot.py", line 110, in get_updates
    result = await self.request(api.Methods.GET_UPDATES, payload)
  File "C:\Users\ww\PycharmProjects\autoshopDjimbo3.1\venv\lib\site-packages\aiogram\bot\base.py", line 231, in request
    return await api.make_request(await self.get_session(), self.server, self.__token, method, data, files,
  File "C:\Users\ww\PycharmProjects\autoshopDjimbo3.1\venv\lib\site-packages\aiogram\bot\api.py", line 140, in make_request
    return check_result(method, response.content_type, response.status, await response.text())
  File "C:\Users\ww\PycharmProjects\autoshopDjimbo3.1\venv\lib\site-packages\aiogram\bot\api.py", line 119, in check_result
    exceptions.ConflictError.detect(description)
  File "C:\Users\ww\PycharmProjects\autoshopDjimbo3.1\venv\lib\site-packages\aiogram\utils\exceptions.py", line 140, in detect
    raise err(cls.text or description)
aiogram.utils.exceptions.TerminatedByOtherGetUpdates: Terminated by other getupdates request; make sure that only one bot instance is running
